<robot
  name="S05" xmlns:xacro="http://www.ros.org/wiki/xacro">
  
  <xacro:include filename="$(find elfin_description)/urdf/materials.xacro" />
  
  <xacro:include filename="$(find elfin_description)/urdf/elfin_robot.gazebo" />
  
  <xacro:include filename="$(find elfin_description)/urdf/elfin_transmission.xacro" />
  
  <xacro:property name="PI" value="3.1415926535897931"/>
  
  <xacro:property name="density" value="3.09"/>
  
  <link name="world"/>
  
  <joint name="world_base" type="fixed">
    <origin
      xyz="0 0 0"
      rpy="0 0 0" />
    <parent
      link="world" />
    <child
      link="elfin_base_link" />
  </joint>
  
  <link name="elfin_base_link"/>
  
  <joint name="elfin_base_joint" type="fixed">
    <origin
      xyz="0 0 0"
      rpy="0 0 0" />
    <parent
      link="elfin_base_link" />
    <child
      link="elfin_base" />
  </joint>
  
  <link
    name="elfin_base">
    <inertial>
      <origin
        xyz="-0.00184437389934045 -6.59500650089517E-06 0.0222886005498919"
        rpy="0 0 0" />
      <mass
        value="0.55783758117095" />
      <inertia
        ixx="0.000806700377609497"
        ixy="6.54161076767138E-09"
        ixz="-9.10804623758884E-06"
        iyy="0.000742642782949531"
        iyz="-6.64350030616068E-08"
        izz="0.00132758561895542" />
    </inertial>
    <visual>
      <origin
        xyz="0 0 0"
        rpy="0 0 0" />
      <geometry>
        <mesh
          filename="package://elfin_description/meshes/S05/base_link.STL" />
      </geometry>
      <material
        name="">
        <color
          rgba="0.792156862745098 0.819607843137255 0.933333333333333 1" />
      </material>
    </visual>
    <collision>
      <origin
        xyz="0 0 0"
        rpy="0 0 0" />
      <geometry>
        <mesh
          filename="package://elfin_description/meshes/S05/base_link.STL" />
      </geometry>
    </collision>
  </link>
  <link
    name="elfin_link1">
    <inertial>
      <origin
        xyz="2.33055077716871E-06 -0.00901454466097123 0.0158738587496875"
        rpy="0 0 0" />
      <mass
        value="2.36455557143755" />
      <inertia
        ixx="0.00451183160259451"
        ixy="-3.26792558903691E-08"
        ixz="7.26054886062041E-08"
        iyy="0.00390660442055615"
        iyz="0.00049262309508953"
        izz="0.00502354133713084" />
    </inertial>
    <visual>
      <origin
        xyz="0 0 0"
        rpy="0 0 0" />
      <geometry>
        <mesh
          filename="package://elfin_description/meshes/S05/elfin_link1.STL" />
      </geometry>
      <material
        name="">
        <color
          rgba="1 1 1 1" />
      </material>
    </visual>
    <collision>
      <origin
        xyz="0 0 0"
        rpy="0 0 0" />
      <geometry>
        <mesh
          filename="package://elfin_description/meshes/S05/elfin_link1.STL" />
      </geometry>
    </collision>
  </link>
  <joint
    name="elfin_joint1"
    type="revolute">
    <origin
      xyz="0 0 0.1215"
      rpy="0 0 0" />
    <parent
      link="elfin_base" />
    <child
      link="elfin_link1" />
    <axis
      xyz="0 0 1" />
  <limit
      lower="-6.28"
      upper="6.28"
      effort="200"
      velocity="1.57" />
  </joint>
  <link
    name="elfin_link2">
    <inertial>
      <origin
        xyz="-0.215001381391909 1.2409870353558E-10 0.0117543388669855"
        rpy="0 0 0" />
      <mass
        value="6.38655762886868" />
      <inertia
        ixx="0.00942144948642947"
        ixy="5.76449595464818E-08"
        ixz="2.12022015866971E-08"
        iyy="0.0224664860505062"
        iyz="-4.19181341688528E-09"
        izz="0.0235010077945909" />
    </inertial>
    <visual>
      <origin
        xyz="0 0 0"
        rpy="0 0 0" />
      <geometry>
        <mesh
          filename="package://elfin_description/meshes/S05/elfin_link2.STL" />
      </geometry>
      <material
        name="">
        <color
          rgba="1 1 1 1" />
      </material>
    </visual>
    <collision>
      <origin
        xyz="0 0 0"
        rpy="0 0 0" />
      <geometry>
        <mesh
          filename="package://elfin_description/meshes/S05/elfin_link2.STL" />
      </geometry>
    </collision>
  </link>
  <joint
    name="elfin_joint2"
    type="revolute">
    <origin
      xyz="0 -0.1585 0"
      rpy="1.5708 0 0" />
    <parent
      link="elfin_link1" />
    <child
      link="elfin_link2" />
    <axis
      xyz="0 0 1" />
    <limit
      lower="-3.3158"
      upper="0.1745"
      effort="200"
      velocity="1.57" />
  </joint>
  <link
    name="elfin_link3">
    <inertial>
      <origin
        xyz="0.171912511860209 2.35345194220804E-05 0.00645788659236412"
        rpy="0 0 0" />
      <mass
        value="2.49272496396584" />
      <inertia
        ixx="0.00266933008860527"
        ixy="-8.56842520060561E-08"
        ixz="0.00178833260512255"
        iyy="0.0190553443992948"
        iyz="-4.05131339576263E-08"
        izz="0.018853980858375" />
    </inertial>
    <visual>
      <origin
        xyz="0 0 0"
        rpy="0 0 0" />
      <geometry>
        <mesh
          filename="package://elfin_description/meshes/S05/elfin_link3.STL" />
      </geometry>
      <material
        name="">
        <color
          rgba="0.792156862745098 0.819607843137255 0.933333333333333 1" />
      </material>
    </visual>
    <collision>
      <origin
        xyz="0 0 0"
        rpy="0 0 0" />
      <geometry>
        <mesh
          filename="package://elfin_description/meshes/S05/elfin_link3.STL" />
      </geometry>
    </collision>
  </link>
  <joint
    name="elfin_joint3"
    type="revolute">
    <origin
      xyz="-0.43 0 -0.1365"
      rpy="0 0 3.1416" />
    <parent
      link="elfin_link2" />
    <child
      link="elfin_link3" />
    <axis
      xyz="0 0 1" />
    <limit
      lower="-2.7574"
      upper="2.7574"
      effort="200"
      velocity="1.57" />
  </joint>
  <link
    name="elfin_link4">
    <inertial>
      <origin
        xyz="8.37197042898863E-05 -0.00267416471329009 0.1090185084264"
        rpy="0 0 0" />
      <mass
        value="0.694773050146191" />
      <inertia
        ixx="0.00073750625094689"
        ixy="1.74143972717691E-08"
        ixz="-7.45292744071859E-09"
        iyy="0.000647584979146833"
        iyz="-9.70101483056526E-05"
        izz="0.0006165532665288" />
    </inertial>
    <visual>
      <origin
        xyz="0 0 0"
        rpy="0 0 0" />
      <geometry>
        <mesh
          filename="package://elfin_description/meshes/S05/elfin_link4.STL" />
      </geometry>
      <material
        name="">
        <color
          rgba="0.752941176470588 0.752941176470588 0.752941176470588 1" />
      </material>
    </visual>
    <collision>
      <origin
        xyz="0 0 0"
        rpy="0 0 0" />
      <geometry>
        <mesh
          filename="package://elfin_description/meshes/S05/elfin_link4.STL" />
      </geometry>
    </collision>
  </link>
  <joint
    name="elfin_joint4"
    type="revolute">
    <origin
      xyz="0.353 0 0"
      rpy="0 0 0" />
    <parent
      link="elfin_link3" />
    <child
      link="elfin_link4" />
    <axis
      xyz="0 0 1" />
   <limit
      lower="-6.28"
      upper="6.28"
      effort="104"
      velocity="1.57" />
  </joint>
  <link
    name="elfin_link5">
    <inertial>
      <origin
        xyz="-8.37261709217829E-05 0.00267415249911426 0.109018502165499"
        rpy="0 0 0" />
      <mass
        value="0.694773165338235" />
      <inertia
        ixx="0.000737506036197175"
        ixy="1.68898703720491E-08"
        ixz="8.03428966986723E-09"
        iyy="0.000647584987534968"
        iyz="9.70101095674385E-05"
        izz="0.000616553577827236" />
    </inertial>
    <visual>
      <origin
        xyz="0 0 0"
        rpy="0 0 0" />
      <geometry>
        <mesh
          filename="package://elfin_description/meshes/S05/elfin_link5.STL" />
      </geometry>
      <material
        name="">
        <color
          rgba="0.752941176470588 0.752941176470588 0.752941176470588 1" />
      </material>
    </visual>
    <collision>
      <origin
        xyz="0 0 0"
        rpy="0 0 0" />
      <geometry>
        <mesh
          filename="package://elfin_description/meshes/S05/elfin_link5.STL" />
      </geometry>
    </collision>
  </link>
  <joint
    name="elfin_joint5"
    type="revolute">
    <origin
      xyz="0 0 0.117"
      rpy="-1.5708 0 0" />
    <parent
      link="elfin_link4" />
    <child
      link="elfin_link5" />
    <axis
      xyz="0 0 1" />
    <limit
      lower="-6.28"
      upper="6.28"
      effort="34"
      velocity="1.57" />
  </joint>
  <link
    name="elfin_link6">
    <inertial>
      <origin
        xyz="-6.99831683009799E-05 -0.00015585757870362 0.082463832632152"
        rpy="0 0 0" />
      <mass
        value="0.288177266982945" />
      <inertia
        ixx="0.000150217389612231"
        ixy="4.97910868291961E-07"
        ixz="3.36683190303104E-08"
        iyy="0.00014836141996132"
        iyz="-5.11427040028956E-08"
        izz="0.000248138450646936" />
    </inertial>
    <visual>
      <origin
        xyz="0 0 0"
        rpy="0 0 0" />
      <geometry>
        <mesh
          filename="package://elfin_description/meshes/S05/elfin_link6.STL" />
      </geometry>
      <material
        name="">
        <color
          rgba="0.792156862745098 0.819607843137255 0.933333333333333 1" />
      </material>
    </visual>
    <collision>
      <origin
        xyz="0 0 0"
        rpy="0 0 0" />
      <geometry>
        <mesh
          filename="package://elfin_description/meshes/S05/elfin_link6.STL" />
      </geometry>
    </collision>
  </link>
  <joint
    name="elfin_joint6"
    type="revolute">
    <origin
      xyz="0 0 0.117"
      rpy="1.5708 0 0" />
    <parent
      link="elfin_link5" />
    <child
      link="elfin_link6" />
    <axis
      xyz="0 0 1" />
    <limit
      lower="-6.28"
      upper="6.28"
      effort="34"
      velocity="1.57" />
  </joint>
  <link
    name="elfin_end_link">
  </link>
  <joint
    name="elfin_end_joint"
    type="fixed">
    <origin
      xyz="0 0 0.11"
      rpy="0 0 -3.1416" />
    <parent
      link="elfin_link6" />
    <child
      link="elfin_end_link" />
  </joint>
  
  <link name="elfin_dummy_gripper"/>
  
  <joint name="elfin_dummy_joint" type="fixed">
    <origin
      xyz="0 -0.0935 0"
      rpy="${PI/2} ${PI/2} 0" />
    <parent
      link="elfin_link6" />
    <child
      link="elfin_dummy_gripper" />
  </joint>
  
</robot>
